[2024-09-25T09:58:42.942+0000] {local_task_job_runner.py:123} INFO - ::group::Pre task execution logs
[2024-09-25T09:58:43.041+0000] {taskinstance.py:2612} INFO - Dependencies all met for dep_context=non-requeueable deps ti=<TaskInstance: etl_pipeline.warehouse.step_1.extract_transform.orders_history scheduled__2024-09-24T00:00:00+00:00 [queued]>
[2024-09-25T09:58:43.094+0000] {taskinstance.py:2612} INFO - Dependencies all met for dep_context=requeueable deps ti=<TaskInstance: etl_pipeline.warehouse.step_1.extract_transform.orders_history scheduled__2024-09-24T00:00:00+00:00 [queued]>
[2024-09-25T09:58:43.095+0000] {taskinstance.py:2865} INFO - Starting attempt 1 of 1
[2024-09-25T09:58:43.174+0000] {taskinstance.py:2888} INFO - Executing <Task(PythonOperator): warehouse.step_1.extract_transform.orders_history> on 2024-09-24 00:00:00+00:00
[2024-09-25T09:58:43.196+0000] {warnings.py:112} WARNING - /home/***/.local/lib/python3.12/site-packages/***/task/task_runner/standard_task_runner.py:70: DeprecationWarning: This process (pid=332) is multi-threaded, use of fork() may lead to deadlocks in the child.
  pid = os.fork()

[2024-09-25T09:58:43.211+0000] {standard_task_runner.py:72} INFO - Started process 353 to run task
[2024-09-25T09:58:43.219+0000] {standard_task_runner.py:104} INFO - Running: ['***', 'tasks', 'run', 'etl_pipeline', 'warehouse.step_1.extract_transform.orders_history', 'scheduled__2024-09-24T00:00:00+00:00', '--job-id', '52', '--raw', '--subdir', 'DAGS_FOLDER/etl_pipeline/run.py', '--cfg-path', '/tmp/tmpiztw4_t5']
[2024-09-25T09:58:43.233+0000] {standard_task_runner.py:105} INFO - Job 52: Subtask warehouse.step_1.extract_transform.orders_history
[2024-09-25T09:58:43.465+0000] {task_command.py:467} INFO - Running <TaskInstance: etl_pipeline.warehouse.step_1.extract_transform.orders_history scheduled__2024-09-24T00:00:00+00:00 [running]> on host 639d778bfb8f
[2024-09-25T09:58:43.823+0000] {taskinstance.py:3131} INFO - Exporting env vars: AIRFLOW_CTX_DAG_OWNER='***' AIRFLOW_CTX_DAG_ID='etl_pipeline' AIRFLOW_CTX_TASK_ID='warehouse.step_1.extract_transform.orders_history' AIRFLOW_CTX_EXECUTION_DATE='2024-09-24T00:00:00+00:00' AIRFLOW_CTX_TRY_NUMBER='1' AIRFLOW_CTX_DAG_RUN_ID='scheduled__2024-09-24T00:00:00+00:00'
[2024-09-25T09:58:43.826+0000] {taskinstance.py:731} INFO - ::endgroup::
[2024-09-25T09:58:43.866+0000] {base.py:84} INFO - Retrieving connection 'staging_db'
[2024-09-25T09:58:46.367+0000] {base.py:84} INFO - Retrieving connection 'warehouse_db'
[2024-09-25T09:58:49.488+0000] {base.py:84} INFO - Retrieving connection 'minio'
[2024-09-25T09:58:49.512+0000] {taskinstance.py:3310} ERROR - Task failed with exception
Traceback (most recent call last):
  File "/home/airflow/.local/lib/python3.12/site-packages/airflow/models/taskinstance.py", line 767, in _execute_task
    result = _execute_callable(context=context, **execute_callable_kwargs)
             ^^^^^^^^^^^^^^^^^^^^^^^^^^^^^^^^^^^^^^^^^^^^^^^^^^^^^^^^^^^^^
  File "/home/airflow/.local/lib/python3.12/site-packages/airflow/models/taskinstance.py", line 733, in _execute_callable
    return ExecutionCallableRunner(
           ^^^^^^^^^^^^^^^^^^^^^^^^
  File "/home/airflow/.local/lib/python3.12/site-packages/airflow/utils/operator_helpers.py", line 252, in run
    return self.func(*args, **kwargs)
           ^^^^^^^^^^^^^^^^^^^^^^^^^^
  File "/home/airflow/.local/lib/python3.12/site-packages/airflow/models/baseoperator.py", line 406, in wrapper
    return func(self, *args, **kwargs)
           ^^^^^^^^^^^^^^^^^^^^^^^^^^^
  File "/home/airflow/.local/lib/python3.12/site-packages/airflow/operators/python.py", line 238, in execute
    return_value = self.execute_callable()
                   ^^^^^^^^^^^^^^^^^^^^^^^
  File "/home/airflow/.local/lib/python3.12/site-packages/airflow/operators/python.py", line 256, in execute_callable
    return runner.run(*self.op_args, **self.op_kwargs)
           ^^^^^^^^^^^^^^^^^^^^^^^^^^^^^^^^^^^^^^^^^^^
  File "/home/airflow/.local/lib/python3.12/site-packages/airflow/utils/operator_helpers.py", line 252, in run
    return self.func(*args, **kwargs)
           ^^^^^^^^^^^^^^^^^^^^^^^^^^
  File "/opt/airflow/dags/etl_pipeline/tasks/warehouse/components/extract_transform.py", line 379, in _orders_history
    CustomMinio._put_csv(data, 'transformed-data', object_name)
  File "/opt/airflow/dags/helper/minio.py", line 25, in _put_csv
    minio_client.put_object(
  File "/home/airflow/.local/lib/python3.12/site-packages/minio/api.py", line 1922, in put_object
    raise exc
  File "/home/airflow/.local/lib/python3.12/site-packages/minio/api.py", line 1868, in put_object
    return self._put_object(
           ^^^^^^^^^^^^^^^^^
  File "/home/airflow/.local/lib/python3.12/site-packages/minio/api.py", line 1707, in _put_object
    response = self._execute(
               ^^^^^^^^^^^^^^
  File "/home/airflow/.local/lib/python3.12/site-packages/minio/api.py", line 437, in _execute
    region = self._get_region(bucket_name)
             ^^^^^^^^^^^^^^^^^^^^^^^^^^^^^
  File "/home/airflow/.local/lib/python3.12/site-packages/minio/api.py", line 494, in _get_region
    response = self._url_open(
               ^^^^^^^^^^^^^^^
  File "/home/airflow/.local/lib/python3.12/site-packages/minio/api.py", line 423, in _url_open
    raise response_error
minio.error.S3Error: S3 operation failed; code: NoSuchBucket, message: The specified bucket does not exist, resource: /transformed-data, request_id: 17F8744C9DB06B5B, host_id: dd9025bab4ad464b049177c95eb6ebf374d3b3fd1af9251148b658df7ac2e3e8, bucket_name: transformed-data
[2024-09-25T09:58:49.533+0000] {taskinstance.py:1225} INFO - Marking task as FAILED. dag_id=etl_pipeline, task_id=warehouse.step_1.extract_transform.orders_history, run_id=scheduled__2024-09-24T00:00:00+00:00, execution_date=20240924T000000, start_date=20240925T095843, end_date=20240925T095849
[2024-09-25T09:58:49.557+0000] {taskinstance.py:340} INFO - ::group::Post task execution logs
[2024-09-25T09:58:49.558+0000] {standard_task_runner.py:124} ERROR - Failed to execute job 52 for task warehouse.step_1.extract_transform.orders_history (S3 operation failed; code: NoSuchBucket, message: The specified bucket does not exist, resource: /transformed-data, request_id: 17F8744C9DB06B5B, host_id: dd9025bab4ad464b049177c95eb6ebf374d3b3fd1af9251148b658df7ac2e3e8, bucket_name: transformed-data; 353)
Traceback (most recent call last):
  File "/home/airflow/.local/lib/python3.12/site-packages/airflow/task/task_runner/standard_task_runner.py", line 117, in _start_by_fork
    ret = args.func(args, dag=self.dag)
          ^^^^^^^^^^^^^^^^^^^^^^^^^^^^^
  File "/home/airflow/.local/lib/python3.12/site-packages/airflow/cli/cli_config.py", line 49, in command
    return func(*args, **kwargs)
           ^^^^^^^^^^^^^^^^^^^^^
  File "/home/airflow/.local/lib/python3.12/site-packages/airflow/utils/cli.py", line 115, in wrapper
    return f(*args, **kwargs)
           ^^^^^^^^^^^^^^^^^^
  File "/home/airflow/.local/lib/python3.12/site-packages/airflow/cli/commands/task_command.py", line 483, in task_run
    task_return_code = _run_task_by_selected_method(args, _dag, ti)
                       ^^^^^^^^^^^^^^^^^^^^^^^^^^^^^^^^^^^^^^^^^^^^
  File "/home/airflow/.local/lib/python3.12/site-packages/airflow/cli/commands/task_command.py", line 256, in _run_task_by_selected_method
    return _run_raw_task(args, ti)
           ^^^^^^^^^^^^^^^^^^^^^^^
  File "/home/airflow/.local/lib/python3.12/site-packages/airflow/cli/commands/task_command.py", line 341, in _run_raw_task
    return ti._run_raw_task(
           ^^^^^^^^^^^^^^^^^
  File "/home/airflow/.local/lib/python3.12/site-packages/airflow/utils/session.py", line 97, in wrapper
    return func(*args, session=session, **kwargs)
           ^^^^^^^^^^^^^^^^^^^^^^^^^^^^^^^^^^^^^^
  File "/home/airflow/.local/lib/python3.12/site-packages/airflow/models/taskinstance.py", line 3004, in _run_raw_task
    return _run_raw_task(
           ^^^^^^^^^^^^^^
  File "/home/airflow/.local/lib/python3.12/site-packages/airflow/models/taskinstance.py", line 273, in _run_raw_task
    TaskInstance._execute_task_with_callbacks(
  File "/home/airflow/.local/lib/python3.12/site-packages/airflow/models/taskinstance.py", line 3158, in _execute_task_with_callbacks
    result = self._execute_task(context, task_orig)
             ^^^^^^^^^^^^^^^^^^^^^^^^^^^^^^^^^^^^^^
  File "/home/airflow/.local/lib/python3.12/site-packages/airflow/models/taskinstance.py", line 3182, in _execute_task
    return _execute_task(self, context, task_orig)
           ^^^^^^^^^^^^^^^^^^^^^^^^^^^^^^^^^^^^^^^
  File "/home/airflow/.local/lib/python3.12/site-packages/airflow/models/taskinstance.py", line 767, in _execute_task
    result = _execute_callable(context=context, **execute_callable_kwargs)
             ^^^^^^^^^^^^^^^^^^^^^^^^^^^^^^^^^^^^^^^^^^^^^^^^^^^^^^^^^^^^^
  File "/home/airflow/.local/lib/python3.12/site-packages/airflow/models/taskinstance.py", line 733, in _execute_callable
    return ExecutionCallableRunner(
           ^^^^^^^^^^^^^^^^^^^^^^^^
  File "/home/airflow/.local/lib/python3.12/site-packages/airflow/utils/operator_helpers.py", line 252, in run
    return self.func(*args, **kwargs)
           ^^^^^^^^^^^^^^^^^^^^^^^^^^
  File "/home/airflow/.local/lib/python3.12/site-packages/airflow/models/baseoperator.py", line 406, in wrapper
    return func(self, *args, **kwargs)
           ^^^^^^^^^^^^^^^^^^^^^^^^^^^
  File "/home/airflow/.local/lib/python3.12/site-packages/airflow/operators/python.py", line 238, in execute
    return_value = self.execute_callable()
                   ^^^^^^^^^^^^^^^^^^^^^^^
  File "/home/airflow/.local/lib/python3.12/site-packages/airflow/operators/python.py", line 256, in execute_callable
    return runner.run(*self.op_args, **self.op_kwargs)
           ^^^^^^^^^^^^^^^^^^^^^^^^^^^^^^^^^^^^^^^^^^^
  File "/home/airflow/.local/lib/python3.12/site-packages/airflow/utils/operator_helpers.py", line 252, in run
    return self.func(*args, **kwargs)
           ^^^^^^^^^^^^^^^^^^^^^^^^^^
  File "/opt/airflow/dags/etl_pipeline/tasks/warehouse/components/extract_transform.py", line 379, in _orders_history
    CustomMinio._put_csv(data, 'transformed-data', object_name)
  File "/opt/airflow/dags/helper/minio.py", line 25, in _put_csv
    minio_client.put_object(
  File "/home/airflow/.local/lib/python3.12/site-packages/minio/api.py", line 1922, in put_object
    raise exc
  File "/home/airflow/.local/lib/python3.12/site-packages/minio/api.py", line 1868, in put_object
    return self._put_object(
           ^^^^^^^^^^^^^^^^^
  File "/home/airflow/.local/lib/python3.12/site-packages/minio/api.py", line 1707, in _put_object
    response = self._execute(
               ^^^^^^^^^^^^^^
  File "/home/airflow/.local/lib/python3.12/site-packages/minio/api.py", line 437, in _execute
    region = self._get_region(bucket_name)
             ^^^^^^^^^^^^^^^^^^^^^^^^^^^^^
  File "/home/airflow/.local/lib/python3.12/site-packages/minio/api.py", line 494, in _get_region
    response = self._url_open(
               ^^^^^^^^^^^^^^^
  File "/home/airflow/.local/lib/python3.12/site-packages/minio/api.py", line 423, in _url_open
    raise response_error
minio.error.S3Error: S3 operation failed; code: NoSuchBucket, message: The specified bucket does not exist, resource: /transformed-data, request_id: 17F8744C9DB06B5B, host_id: dd9025bab4ad464b049177c95eb6ebf374d3b3fd1af9251148b658df7ac2e3e8, bucket_name: transformed-data
[2024-09-25T09:58:49.617+0000] {local_task_job_runner.py:266} INFO - Task exited with return code 1
[2024-09-25T09:58:49.676+0000] {taskinstance.py:3900} INFO - 0 downstream tasks scheduled from follow-on schedule check
[2024-09-25T09:58:49.680+0000] {local_task_job_runner.py:245} INFO - ::endgroup::
