[2024-09-25T08:49:11.302+0000] {local_task_job_runner.py:123} INFO - ::group::Pre task execution logs
[2024-09-25T08:49:11.389+0000] {taskinstance.py:2612} INFO - Dependencies all met for dep_context=non-requeueable deps ti=<TaskInstance: etl_pipeline.dellstore_db.extract.customers scheduled__2024-09-24T00:00:00+00:00 [queued]>
[2024-09-25T08:49:11.430+0000] {taskinstance.py:2612} INFO - Dependencies all met for dep_context=requeueable deps ti=<TaskInstance: etl_pipeline.dellstore_db.extract.customers scheduled__2024-09-24T00:00:00+00:00 [queued]>
[2024-09-25T08:49:11.431+0000] {taskinstance.py:2865} INFO - Starting attempt 1 of 1
[2024-09-25T08:49:11.477+0000] {taskinstance.py:2888} INFO - Executing <Task(PythonOperator): dellstore_db.extract.customers> on 2024-09-24 00:00:00+00:00
[2024-09-25T08:49:11.544+0000] {warnings.py:112} WARNING - /home/***/.local/lib/python3.12/site-packages/***/task/task_runner/standard_task_runner.py:70: DeprecationWarning: This process (pid=295) is multi-threaded, use of fork() may lead to deadlocks in the child.
  pid = os.fork()

[2024-09-25T08:49:11.561+0000] {standard_task_runner.py:72} INFO - Started process 306 to run task
[2024-09-25T08:49:11.634+0000] {standard_task_runner.py:104} INFO - Running: ['***', 'tasks', 'run', 'etl_pipeline', 'dellstore_db.extract.customers', 'scheduled__2024-09-24T00:00:00+00:00', '--job-id', '8', '--raw', '--subdir', 'DAGS_FOLDER/etl_pipeline/run.py', '--cfg-path', '/tmp/tmpvcpjpc0o']
[2024-09-25T08:49:11.719+0000] {standard_task_runner.py:105} INFO - Job 8: Subtask dellstore_db.extract.customers
[2024-09-25T08:49:12.358+0000] {task_command.py:467} INFO - Running <TaskInstance: etl_pipeline.dellstore_db.extract.customers scheduled__2024-09-24T00:00:00+00:00 [running]> on host 857abb7f2bfc
[2024-09-25T08:49:12.980+0000] {taskinstance.py:3131} INFO - Exporting env vars: AIRFLOW_CTX_DAG_OWNER='***' AIRFLOW_CTX_DAG_ID='etl_pipeline' AIRFLOW_CTX_TASK_ID='dellstore_db.extract.customers' AIRFLOW_CTX_EXECUTION_DATE='2024-09-24T00:00:00+00:00' AIRFLOW_CTX_TRY_NUMBER='1' AIRFLOW_CTX_DAG_RUN_ID='scheduled__2024-09-24T00:00:00+00:00'
[2024-09-25T08:49:12.993+0000] {taskinstance.py:731} INFO - ::endgroup::
[2024-09-25T08:49:13.116+0000] {base.py:84} INFO - Retrieving connection 'dellstore_db'
[2024-09-25T08:49:13.693+0000] {taskinstance.py:3310} ERROR - Task failed with exception
Traceback (most recent call last):
  File "/opt/airflow/dags/etl_pipeline/tasks/staging/components/extract.py", line 52, in _dellstore_db
    raise AirflowSkipException(f"{table_name} doesn't have new data. Skipped...")
airflow.exceptions.AirflowSkipException: customers doesn't have new data. Skipped...

During handling of the above exception, another exception occurred:

Traceback (most recent call last):
  File "/home/airflow/.local/lib/python3.12/site-packages/airflow/models/taskinstance.py", line 767, in _execute_task
    result = _execute_callable(context=context, **execute_callable_kwargs)
             ^^^^^^^^^^^^^^^^^^^^^^^^^^^^^^^^^^^^^^^^^^^^^^^^^^^^^^^^^^^^^
  File "/home/airflow/.local/lib/python3.12/site-packages/airflow/models/taskinstance.py", line 733, in _execute_callable
    return ExecutionCallableRunner(
           ^^^^^^^^^^^^^^^^^^^^^^^^
  File "/home/airflow/.local/lib/python3.12/site-packages/airflow/utils/operator_helpers.py", line 252, in run
    return self.func(*args, **kwargs)
           ^^^^^^^^^^^^^^^^^^^^^^^^^^
  File "/home/airflow/.local/lib/python3.12/site-packages/airflow/models/baseoperator.py", line 406, in wrapper
    return func(self, *args, **kwargs)
           ^^^^^^^^^^^^^^^^^^^^^^^^^^^
  File "/home/airflow/.local/lib/python3.12/site-packages/airflow/operators/python.py", line 238, in execute
    return_value = self.execute_callable()
                   ^^^^^^^^^^^^^^^^^^^^^^^
  File "/home/airflow/.local/lib/python3.12/site-packages/airflow/operators/python.py", line 256, in execute_callable
    return runner.run(*self.op_args, **self.op_kwargs)
           ^^^^^^^^^^^^^^^^^^^^^^^^^^^^^^^^^^^^^^^^^^^
  File "/home/airflow/.local/lib/python3.12/site-packages/airflow/utils/operator_helpers.py", line 252, in run
    return self.func(*args, **kwargs)
           ^^^^^^^^^^^^^^^^^^^^^^^^^^
  File "/opt/airflow/dags/etl_pipeline/tasks/staging/components/extract.py", line 62, in _dellstore_db
    raise AirflowException(f"Error when extracting {table_name} : {str(e)}")
airflow.exceptions.AirflowException: Error when extracting customers : customers doesn't have new data. Skipped...
[2024-09-25T08:49:13.703+0000] {taskinstance.py:1225} INFO - Marking task as FAILED. dag_id=etl_pipeline, task_id=dellstore_db.extract.customers, run_id=scheduled__2024-09-24T00:00:00+00:00, execution_date=20240924T000000, start_date=20240925T084911, end_date=20240925T084913
[2024-09-25T08:49:13.796+0000] {taskinstance.py:340} INFO - ::group::Post task execution logs
[2024-09-25T08:49:13.797+0000] {standard_task_runner.py:124} ERROR - Failed to execute job 8 for task dellstore_db.extract.customers (Error when extracting customers : customers doesn't have new data. Skipped...; 306)
Traceback (most recent call last):
  File "/opt/airflow/dags/etl_pipeline/tasks/staging/components/extract.py", line 52, in _dellstore_db
    raise AirflowSkipException(f"{table_name} doesn't have new data. Skipped...")
airflow.exceptions.AirflowSkipException: customers doesn't have new data. Skipped...

During handling of the above exception, another exception occurred:

Traceback (most recent call last):
  File "/home/airflow/.local/lib/python3.12/site-packages/airflow/task/task_runner/standard_task_runner.py", line 117, in _start_by_fork
    ret = args.func(args, dag=self.dag)
          ^^^^^^^^^^^^^^^^^^^^^^^^^^^^^
  File "/home/airflow/.local/lib/python3.12/site-packages/airflow/cli/cli_config.py", line 49, in command
    return func(*args, **kwargs)
           ^^^^^^^^^^^^^^^^^^^^^
  File "/home/airflow/.local/lib/python3.12/site-packages/airflow/utils/cli.py", line 115, in wrapper
    return f(*args, **kwargs)
           ^^^^^^^^^^^^^^^^^^
  File "/home/airflow/.local/lib/python3.12/site-packages/airflow/cli/commands/task_command.py", line 483, in task_run
    task_return_code = _run_task_by_selected_method(args, _dag, ti)
                       ^^^^^^^^^^^^^^^^^^^^^^^^^^^^^^^^^^^^^^^^^^^^
  File "/home/airflow/.local/lib/python3.12/site-packages/airflow/cli/commands/task_command.py", line 256, in _run_task_by_selected_method
    return _run_raw_task(args, ti)
           ^^^^^^^^^^^^^^^^^^^^^^^
  File "/home/airflow/.local/lib/python3.12/site-packages/airflow/cli/commands/task_command.py", line 341, in _run_raw_task
    return ti._run_raw_task(
           ^^^^^^^^^^^^^^^^^
  File "/home/airflow/.local/lib/python3.12/site-packages/airflow/utils/session.py", line 97, in wrapper
    return func(*args, session=session, **kwargs)
           ^^^^^^^^^^^^^^^^^^^^^^^^^^^^^^^^^^^^^^
  File "/home/airflow/.local/lib/python3.12/site-packages/airflow/models/taskinstance.py", line 3004, in _run_raw_task
    return _run_raw_task(
           ^^^^^^^^^^^^^^
  File "/home/airflow/.local/lib/python3.12/site-packages/airflow/models/taskinstance.py", line 273, in _run_raw_task
    TaskInstance._execute_task_with_callbacks(
  File "/home/airflow/.local/lib/python3.12/site-packages/airflow/models/taskinstance.py", line 3158, in _execute_task_with_callbacks
    result = self._execute_task(context, task_orig)
             ^^^^^^^^^^^^^^^^^^^^^^^^^^^^^^^^^^^^^^
  File "/home/airflow/.local/lib/python3.12/site-packages/airflow/models/taskinstance.py", line 3182, in _execute_task
    return _execute_task(self, context, task_orig)
           ^^^^^^^^^^^^^^^^^^^^^^^^^^^^^^^^^^^^^^^
  File "/home/airflow/.local/lib/python3.12/site-packages/airflow/models/taskinstance.py", line 767, in _execute_task
    result = _execute_callable(context=context, **execute_callable_kwargs)
             ^^^^^^^^^^^^^^^^^^^^^^^^^^^^^^^^^^^^^^^^^^^^^^^^^^^^^^^^^^^^^
  File "/home/airflow/.local/lib/python3.12/site-packages/airflow/models/taskinstance.py", line 733, in _execute_callable
    return ExecutionCallableRunner(
           ^^^^^^^^^^^^^^^^^^^^^^^^
  File "/home/airflow/.local/lib/python3.12/site-packages/airflow/utils/operator_helpers.py", line 252, in run
    return self.func(*args, **kwargs)
           ^^^^^^^^^^^^^^^^^^^^^^^^^^
  File "/home/airflow/.local/lib/python3.12/site-packages/airflow/models/baseoperator.py", line 406, in wrapper
    return func(self, *args, **kwargs)
           ^^^^^^^^^^^^^^^^^^^^^^^^^^^
  File "/home/airflow/.local/lib/python3.12/site-packages/airflow/operators/python.py", line 238, in execute
    return_value = self.execute_callable()
                   ^^^^^^^^^^^^^^^^^^^^^^^
  File "/home/airflow/.local/lib/python3.12/site-packages/airflow/operators/python.py", line 256, in execute_callable
    return runner.run(*self.op_args, **self.op_kwargs)
           ^^^^^^^^^^^^^^^^^^^^^^^^^^^^^^^^^^^^^^^^^^^
  File "/home/airflow/.local/lib/python3.12/site-packages/airflow/utils/operator_helpers.py", line 252, in run
    return self.func(*args, **kwargs)
           ^^^^^^^^^^^^^^^^^^^^^^^^^^
  File "/opt/airflow/dags/etl_pipeline/tasks/staging/components/extract.py", line 62, in _dellstore_db
    raise AirflowException(f"Error when extracting {table_name} : {str(e)}")
airflow.exceptions.AirflowException: Error when extracting customers : customers doesn't have new data. Skipped...
[2024-09-25T08:49:13.857+0000] {local_task_job_runner.py:266} INFO - Task exited with return code 1
[2024-09-25T08:49:13.872+0000] {local_task_job_runner.py:245} INFO - ::endgroup::
